<mujoco model="pick_place">
    <compiler angle="radian"/>
    <option gravity="0 0 -9.81"/>

    <worldbody>
        <!-- Flat ground -->
        <geom name="floor" type="plane" size="1 1 0.1" rgba="0.8 0.8 0.8 1"/>

        <!-- 2-link robot arm -->
        <body name="base" pos="0 0 0.02">
            <body name="link1" pos="0 0 0.0">
                <joint name="joint1" type="hinge" axis="0 0 1" range="-3.14 3.14"/>
                <geom type="capsule" fromto="0 0 0  0 0.3 0" size="0.02" rgba="0 0 1 1" contype="1" conaffinity="1"/>

                <body name="link2" pos="0 0.3 0">
                    <joint name="joint2" type="hinge" axis="0 0 1" range="-3.14 3.14"/>
                    <geom type="capsule" fromto="0 0 0  0 0.3 0" size="0.02" rgba="0 0 1 1" contype="1" conaffinity="1"/>

                    <!-- Gripper site -->
                    <site name="grip_site" pos="0 0.3 0" size="0.02" rgba="0 1 0 1"/>
                </body>
            </body>
        </body>

        <!-- Object to pick -->
        <body name="object" pos="0.3 0.2 0.02">
            <joint name="obj_free" type="free" />
            <geom name="object_geom" type="box" size="0.02 0.02 0.02" rgba="1 0 0 1" mass="0.1" contype="1" conaffinity="1"/>
        </body>

        <!-- Goal position -->
        <site name="goal_site" pos="0.5 0.1 0.02" size="0.02" rgba="0 1 0 1"/>
    </worldbody>

    <actuator>
        <motor joint="joint1" ctrlrange="-1 1" gear="1"/>
        <motor joint="joint2" ctrlrange="-1 1" gear="1"/>
    </actuator>
</mujoco>
